Workbook

Sheet Cover
B2: John Starrett's Foundation & Pre-Super Base
B3: The Stablemaster's on-ramp — what a newer, slower runner does BEFORE the Super Base
B5: Workbook | F5: Phase Roadmap
B6: Version | C6: 1.0.0 | F6: Pre-Foundation | G6: ● v1.0.0 (implemented)
B7: Build date | C7: July 23, 2026 | F7: Foundation | G7: ● v1.0.0 (implemented)
B8: Phases implemented | C8: Pre-Foundation + Foundation + Pre-Super Base | F8: Pre-Super Base | G8: ● v1.0.0 (implemented)
B9: Structure | C9: ≈2 wk on-ramp + 10 wk Foundation + 8 wk Pre-Super Base | F9: Super Base | G9: → separate workbook
B10: Weekly rhythm | C10: 4 runs/wk (Tue/Wed/Fri/Sat) + 3 rest days | F10: Marathon Bridge | G10: ○ Future
B11: Built for | C11: A newer, slower, low-volume runner (expanded per John's advice) | F11: Marathon Specific | G11: ○ Future
B12: Leads into | C12: The Super Base workbook (starts once 3x65 + 90 easy is comfortable)
B14: Coach Philosophy for this stage — the short version
B15: • You are (for now) a 'shuffler': hip-flexor dominant. The whole point of this block is to fix that BEFORE any real speed work.
B16: • Too much too soon is how beginners get hurt — shin splints / medial tibial stress. Build the musculoskeletal system first.
B17: • Foundation = get to 3x65 min easy + 1x90 min easy, comfortably. No tempo, no intervals. Just time on feet, run by feel.
B18: • Pre-Super Base = rewire the stride. Hill blasts + aerobic strides turn the shuffle into a glute-driven, economical run.
B19: • Slower / newer runners get an ELONGATED block — John says so explicitly. Time is on your side. Don't rush to the Super Base.
B20: • Four runs a week beats three: three is maintenance, four lets you progress with less injury risk.
B21: • Only move to the Super Base once the long run and easy runs feel genuinely comfortable and form has changed.
B23: Navigate
B24: Inputs | C24: → | D24: Dashboard | E24: → | F24: Calendar | G24: →
B25: Workout Library | C25: → | D25: Paces | E25: → | F25: Coach Philosophy | G25: →
B26: Progress Log | C26: →

Sheet Inputs
B2: Inputs
B3: Yellow cells are yours to edit. Dates and the calendar derive from these.
B5: Athlete | E5: How this workbook flows
B6: Name | C6: Friend | E6: 1. Inputs — Set the start date here. Everything in the calendar derives from it.
E7: 2. Dashboard — Where you are today: current week, phase, this week's runs.
B8: Pace | E8: 3. Calendar — The full day-by-day plan across all phases.
B9: Current easy pace — min/mi (optional, info only) | C9: 10:30 | E9: 4. Workout Library — Read the hill-blast & aerobic-stride cards BEFORE your first one.
B10: Note | C10: For your reference only — nothing computes off pace. This block is run 100% by feel. | E10: 5. Paces — There are almost no pace targets here on purpose. Run by feel/effort.
E11: 6. Coach Philosophy — Why this on-ramp exists and what it's doing to your body.
E12: 7. Progress Log — One row per day. Mark status; the Dashboard updates automatically.
B14: Dates
B15: Start date (Monday of Week 1) | C15: 46237
B16: Plan end date (Sunday of final week) — derived | C16: =C15+139 -> 46376
B18: Plan structure
B19: Total duration | C19: ≈20 weeks (expanded for a newer/slower runner)
B20: Pre-Foundation (on-ramp) | C20: 2 weeks — jog-walk / very short easy runs
B21: Foundation | C21: 10 weeks — build to 3x65 easy + 1x90 easy (John's canonical is ~7; lengthened here)
B22: Pre-Super Base | C22: 8 weeks — hill blasts + aerobic strides (John's canonical is ~7; +1 buffer)
B23: Runs per week | C23: 4 (Tue/Wed/Fri/Sat)
B24: Then | C24: Move to the Super Base workbook
B26: Why longer than John's default? | C26: John: for a very de-conditioned runner he starts at ~35-min runs and runs an 'elongated pre super base ... rather than the seven weeks it normally takes.' Progress 5-10 min/week by feel, gated on injury history/age/time. Sources on Coach Philosophy tab.

Sheet Dashboard
B2: Dashboard
B3: Where you are today. Refreshes from Inputs and the Progress Log.
B5: CURRENT WEEK | E5: CURRENT PHASE
B6: =IF(TODAY()<Inputs!$C$15,0,MIN(20,INT((TODAY()-Inputs!$C$15)/7)+1)) -> 0 | E6: =IF(B6=0,"Not started",INDEX('Progress Log'!$D$5:$D$1000,MATCH(B6,'Progress Log'!$C$5:$C$1000,0))) -> Not started
B8: TOTAL WEEKS | E8: COMPLETION
B9: 20 | E9: =IFERROR(COUNTIF('Progress Log'!$G$5:$G$1000,"Completed")/COUNTA('Progress Log'!$F$5:$F$1000),0) -> 0
B11: This week's runs
B12: Tue | C12: =IFERROR(INDEX(Calendar!$F$4:$F$1000,MATCH($B$6,Calendar!$B$4:$B$1000,0)),"")
B13: Wed — KEY | C13: =IFERROR(INDEX(Calendar!$G$4:$G$1000,MATCH($B$6,Calendar!$B$4:$B$1000,0)),"")
B14: Fri | C14: =IFERROR(INDEX(Calendar!$I$4:$I$1000,MATCH($B$6,Calendar!$B$4:$B$1000,0)),"")
B15: Sat — KEY/LONG | C15: =IFERROR(INDEX(Calendar!$J$4:$J$1000,MATCH($B$6,Calendar!$B$4:$B$1000,0)),"")
B17: Status tally
B18: Completed | C18: =COUNTIF('Progress Log'!$G$5:$G$1000,"Completed") -> 0
B19: Modified | C19: =COUNTIF('Progress Log'!$G$5:$G$1000,"Modified") -> 0
B20: Missed | C20: =COUNTIF('Progress Log'!$G$5:$G$1000,"Missed") -> 0

Sheet Calendar
B2: Foundation & Pre-Super Base Calendar
B3: Wk | C3: Week of | D3: Phase | E3: Mon | F3: Tue | G3: Wed — KEY | H3: Thu | I3: Fri | J3: Sat — KEY / LONG | K3: Sun | L3: Weekly notes
B4: 1 | C4: =Inputs!$C$15+0 -> 46237 | D4: Pre-Foundation 1 | E4: Rest or 20 min walk | F4: Jog-walk 25 min (e.g. 3 min jog / 1 min walk) | G4: Jog-walk 25 min easy | H4: Rest or 20 min walk | I4: Jog-walk 25 min easy | J4: Jog-walk 30 min easy | K4: Rest | L4: On-ramp. Goal is simply to get the body used to being on its feet. All by feel, conversational. If a niggle appears, walk more. Skip if you already run 30+ min comfortably.
B5: 2 | C5: =Inputs!$C$15+7 -> 46244 | D5: Pre-Foundation 2 | E5: Rest or 20 min walk | F5: Easy run 30 min (walk breaks as needed) | G5: Easy run 30 min | H5: Rest or 20 min walk | I5: Easy run 30 min | J5: Easy run 35 min | K5: Rest | L5: Bridging to Foundation. When you can run ~35 min continuously and easily, you're ready for Week 1 of Foundation. No rush.
B6: 3 | C6: =Inputs!$C$15+14 -> 46251 | D6: Foundation 1 | E6: Rest / cross-train | F6: Easy 35 min | G6: Easy 35 min | H6: Rest / cross-train | I6: Easy 35 min | J6: Long run 40 min easy (no tempo) | K6: Rest | L6: Foundation begins. Three easy runs + one slightly longer. Everything conversational — you should be able to talk in full sentences.
B7: 4 | C7: =Inputs!$C$15+21 -> 46258 | D7: Foundation 2 | E7: Rest / cross-train | F7: Easy 40 min | G7: Easy 40 min | H7: Rest / cross-train | I7: Easy 40 min | J7: Long run 45 min easy (no tempo) | K7: Rest | L7: Add ~5 min. Same effort. If last week felt hard or a niggle showed up, repeat the previous week instead — that's a feature, not failure.
B8: 5 | C8: =Inputs!$C$15+28 -> 46265 | D8: Foundation 3 | E8: Rest / cross-train | F8: Easy 45 min | G8: Easy 40 min | H8: Rest / cross-train | I8: Easy 45 min | J8: Long run 50 min easy (no tempo) | K8: Rest | L8: Long run creeps toward an hour. Easy runs leading it. Watch for shin/calf tightness — that's the classic beginner warning sign.
B9: 6 | C9: =Inputs!$C$15+35 -> 46272 | D9: Foundation 4 | E9: Rest / cross-train | F9: Easy 50 min | G9: Easy 45 min | H9: Rest / cross-train | I9: Easy 50 min | J9: Long run 55 min easy (no tempo) | K9: Rest | L9: Consolidation. Note how the same pace is starting to feel easier and heart rate drifts down — that's the base being laid.
B10: 7 | C10: =Inputs!$C$15+42 -> 46279 | D10: Foundation 5 | E10: Rest / cross-train | F10: Easy 55 min | G10: Easy 50 min | H10: Rest / cross-train | I10: Easy 55 min | J10: Long run 60 min easy (no tempo) | K10: Rest | L10: Long run hits 60 min. Big milestone. Keep it strictly easy — no showing off on the long run.
B11: 8 | C11: =Inputs!$C$15+49 -> 46286 | D11: Foundation 6 | E11: Rest / cross-train | F11: Easy 60 min | G11: Easy 55 min | H11: Rest / cross-train | I11: Easy 60 min | J11: Long run 70 min easy (no tempo) | K11: Rest | L11: Long run past an hour. If life/energy is tight this week, hold volume flat — consistency beats heroics.
B12: 9 | C12: =Inputs!$C$15+56 -> 46293 | D12: Foundation 7 | E12: Rest / cross-train | F12: Easy 60 min | G12: Easy 60 min | H12: Rest / cross-train | I12: Easy 60 min | J12: Long run 75 min easy (no tempo) | K12: Rest | L12: All easy runs at ~60 now. Long run building. You're most of the way to the Foundation target.
B13: 10 | C13: =Inputs!$C$15+63 -> 46300 | D13: Foundation 8 | E13: Rest / cross-train | F13: Easy 65 min | G13: Easy 60 min | H13: Rest / cross-train | I13: Easy 65 min | J13: Long run 80 min easy (no tempo) | K13: Rest | L13: First 65-min easy run. Long run 80. If everything feels comfortable, press on; if not, sit here another week.
B14: 11 | C14: =Inputs!$C$15+70 -> 46307 | D14: Foundation 9 | E14: Rest / cross-train | F14: Easy 65 min | G14: Easy 65 min | H14: Rest / cross-train | I14: Easy 65 min | J14: Long run 85 min easy (no tempo) | K14: Rest | L14: Two 65s in. One more easy run and ~5 min on the long run to go. Do NOT rush this — 'too much too soon' is the enemy.
B15: 12 | C15: =Inputs!$C$15+77 -> 46314 | D15: Foundation 10 | E15: Rest / cross-train | F15: Easy 65 min | G15: Easy 65 min | H15: Rest / cross-train | I15: Easy 65 min | J15: Long run 90 min easy (no tempo) | K15: Rest | L15: FOUNDATION COMPLETE (target reached): 3x65 easy + 1x90 easy, comfortably. If it isn't yet comfortable, repeat weeks until it is, THEN start Pre-Super Base.
B16: 13 | C16: =Inputs!$C$15+84 -> 46321 | D16: Pre-Super Base 1 | E16: Rest / cross-train | F16: Easy 65 min | G16: WU + 3x(5x20s @ 5K effort, jog-back recovery) w/ 3 min jog between sets + CD | H16: Rest / cross-train | I16: Easy 45-50 min (or rest if legs are heavy from strides/hills) | J16: Hill blasts: WU + drills + 4x 8-sec blasts (2:30 walk recovery). Tall/relaxed/piston/pop. | then/next day: Long run 90 min easy | K16: Rest | L16: Pre-Super Base begins — the stride-rewiring block. Week rhythm: 1 easy 65, aerobic strides, hill blasts, long run 90. Long run STAYS at 90 all block — just time on feet.
B17: 14 | C17: =Inputs!$C$15+91 -> 46328 | D17: Pre-Super Base 2 | E17: Rest / cross-train | F17: Easy 65 min | G17: WU + 3x(5x30s @ 5K effort, jog-back) w/ 3 min jog between sets + CD | H17: Rest / cross-train | I17: Easy 45-50 min (or rest if legs are heavy from strides/hills) | J17: Hill blasts: WU + drills + 4x 8-sec blasts (2:30 walk). Film yourself; check form. | then/next day: Long run 90 min easy | K17: Rest | L17: Hill blasts + strides work synergistically: the hill-blast form (glutes, hip extension) leaks into the strides and then into your easy running. Read the Workout Library cards.
B18: 15 | C18: =Inputs!$C$15+98 -> 46335 | D18: Pre-Super Base 3 | E18: Rest / cross-train | F18: Easy 65 min | G18: WU + 3x(5x40s @ 5K effort, jog-back) w/ 3 min jog between sets + CD | H18: Rest / cross-train | I18: Easy 45-50 min (or rest if legs are heavy from strides/hills) | J18: Hill blasts: WU + drills + 6x 8-sec blasts (2:30 walk recovery). | then/next day: Long run 90 min easy | K18: Rest | L18: Strides now 40s. You may notice easy-run pace drifting faster at the SAME effort, heart rate lower — that's improving running economy, exactly the goal.
B19: 16 | C19: =Inputs!$C$15+105 -> 46342 | D19: Pre-Super Base 4 | E19: Rest / cross-train | F19: Easy 65 min | G19: WU + 3x(5x40s) + 3 min jog + 2 min @ 5K effort add-on + CD | H19: Rest / cross-train | I19: Easy 45-50 min (or rest if legs are heavy from strides/hills) | J19: Hill blasts: WU + drills + 6x 8-sec blasts (2:30 walk recovery). | then/next day: Long run 90 min easy | K19: Rest | L19: Add-on begins (2 min). The strides session starts to feel like a light workout at the tail end. Recoveries stay generous — stimulate, don't annihilate.
B20: 17 | C20: =Inputs!$C$15+112 -> 46349 | D20: Pre-Super Base 5 | E20: Rest / cross-train | F20: Easy 65 min | G20: WU + 3x(5x40s) + 3 min jog + 3 min @ 5K effort add-on + CD | H20: Rest / cross-train | I20: Easy 45-50 min (or rest if legs are heavy from strides/hills) | J20: Hill blasts: WU + drills + 8x 8-sec blasts (2:30 walk recovery). | then/next day: Long run 90 min easy | K20: Rest | L20: Add-on 3 min. Hill blasts at full 8 reps now. If Achilles/calf grumbles, skip hill blasts and keep strides only — hill blasts are optional if injury-prone.
B21: 18 | C21: =Inputs!$C$15+119 -> 46356 | D21: Pre-Super Base 6 | E21: Rest / cross-train | F21: Easy 65 min | G21: WU + 3x(5x40s) + 3 min jog + 4 min @ 5K effort add-on + CD | H21: Rest / cross-train | I21: Easy 45-50 min (or rest if legs are heavy from strides/hills) | J21: Hill blasts: WU + drills + 8x 8-sec blasts (2:30 walk recovery). | then/next day: Long run 90 min easy | K21: Rest | L21: Add-on 4 min — this one bites a little. That's fine. Still finish feeling you could do 1-2 more.
B22: 19 | C22: =Inputs!$C$15+126 -> 46363 | D22: Pre-Super Base 7 | E22: Rest / cross-train | F22: Easy 65 min | G22: WU + 3x(5x40s) + 3 min jog + 5 min @ 5K effort add-on + CD (peak stride session) | H22: Rest / cross-train | I22: Easy 45-50 min (or rest if legs are heavy from strides/hills) | J22: Hill blasts: WU + drills + 8x 8-sec blasts (2:30 walk recovery). | then/next day: Long run 90 min easy | K22: Rest | L22: Add-on 5 min — peak Pre-Super Base session. The 5-min add-on will often be FASTER than your very first 20s stride felt. That's the whole trick working.
B23: 20 | C23: =Inputs!$C$15+133 -> 46370 | D23: Pre-Super Base 8 | E23: Rest / cross-train | F23: Easy 65 min | G23: Repeat: WU + 3x(5x40s) + 3 min jog + 5 min add-on + CD (consolidate, form dialled) | H23: Rest / cross-train | I23: Easy 45-50 min (or rest if legs are heavy from strides/hills) | J23: Hill blasts: WU + drills + 8x 8-sec blasts (2:30 walk recovery). | then/next day: Long run 90 min easy | K23: Rest | L23: Consolidation / bridge week. Form should now feel automatic. When it does, you're ready for the SUPER BASE workbook. If not, hold here another week or two.

Sheet Workout Library
B2: Workout Library
B3: The Stazza sessions used in this on-ramp. Read the card BEFORE you run the workout.
B5: Easy Run
B6: Purpose | C6: The backbone of Foundation. Time on feet to build the musculoskeletal system and teach you to run by feel. This is where beginners get hurt by going too fast — don't.
B7: Effort | C7: Conversational. Full sentences. Nose-breathing when possible. If you can't chat, you're too fast.
B8: Structure | C8: Continuous. Walk breaks are completely fine early on — jog-walk your way up.
B9: Progression | C9: Add 5-10 min per week, gated on how you feel. Injury history, age, sleep, life stress all lower the safe rate. Repeat a week whenever needed.
B10: Coach note | C10: John starts genuinely new/de-conditioned runners at ~35 min and builds to 3x65 + 90. Slower runners take longer — that's expected, not a problem.
B11: Common mistakes | C11: Running easy runs at moderate pace. Chasing Strava. Adding minutes faster than the body adapts.
B13: Long Run (Foundation)
B14: Purpose | C14: One longer easy run per week. Accustom the body to time and distance on feet. No tempo, no surges.
B15: Effort | C15: Same easy, conversational effort as the easy runs — just longer.
B16: Structure | C16: Build toward 90 min. In Pre-Super Base it STAYS at 90 (does not grow) — the body is getting used to that duration.
B17: Coach note | C17: 'Just 90 minutes easy. There's no tempo in it. It doesn't go any longer than that.' The long run only starts carrying real work once you reach the Super Base.
B19: Hill Blasts (the magic session)
B20: Purpose | C20: John's 'best bang for buck' session. Rewires a hip-flexor 'shuffle' into a glute-driven stride. Improves running economy, power, stride length. THIS is what unlocks the later speed.
B21: The hill | C21: Shallow — about 5 degrees (a motorway flyover works). Steeper only if you're under ~30 and injury-free. Over 35: shallow, always.
B22: The rep | C22: 8 seconds, ~95-98% effort but controlled — NOT an all-out sprint. Find a fixed landmark = your 8-sec mark, forever.
B23: Recovery | C23: 2 min 30 WALK between reps. Long recovery is deliberate: the CP (creatine-phosphate) energy system takes ~2:30 to replenish. Don't jog it — walk.
B24: Reps | C24: Start 4, then 6, then hold at 8. WU 20-30 min + drills (high knees, straight-leg march) first.
B25: The mantra | C25: 'TALL — RELAXED — PISTON — POP POP POP.' Tall = perpendicular to the hill (engages glutes). Relaxed = breathe, don't tense. Piston = arms drive back, hand brushes hip, elbow to ~shoulder height behind you (this opens the stride). Pop = feet pop off like hot coals.
B26: Feel check | C26: It should feel awkward — 'like riding a bicycle up the hill,' heels coming up under the butt automatically. That awkwardness means it's working. Film yourself from the side to check.
B27: Skip if | C27: Achilles/calf injury history — hill blasts load these. Keep aerobic strides only in that case.
B29: Aerobic Strides (John Kellogg style)
B30: Purpose | C30: Neuromuscular / economy work that pairs synergistically with the hill blasts. 'Aerobic' is a misnomer (all energy systems fire) — named for the generous recovery.
B31: The rep | C31: 20s (building to 30s, then 40s) at roughly 5K effort. To a landmark, stop, turn, jog back. Relaxed, not strained.
B32: Structure | C32: 3 sets of 5 reps, 3 min jog between sets. Weeks 1-3: grow rep 20>30>40s. Week 4+: hold 3x5x40s, then add a 2>3>4>5 min continuous block at 5K effort at the end.
B33: Coach note | C33: By the 5-min add-on, you'll likely be running FASTER than your first 20s stride felt — because the hill blasts have improved your economy. That transfer is the whole point.
B34: Common mistakes | C34: Turning it into a hard interval session early. Cutting the recovery. Sprinting the reps.
B36: Drills (before hill blasts)
B37: Purpose | C37: Break the stride down and wake up the neural pathways ('brain talking to the butt') before hill blasts.
B38: Examples | C38: High knees ~20 m, then jog back; straight-leg marching ~20 m, then jog back. Optionally a 20 m stride after each to reinforce.
B39: When | C39: As part of the hill-blast warm-up only. Not a standalone session.
B41: Rest / Cross-train
B42: Purpose | C42: Recovery IS training — adaptation happens between runs, not during them. Three rest days a week is engineering, not laziness.
B43: Options | C43: Full rest, an easy walk, or low-impact cross-training (easy bike/swim) if you want movement without pounding.
B44: Rule | C44: Never turn a rest day into a secret run. If you feel great, that's the plan working — bank it, don't spend it.

Sheet Paces
B2: Paces & Effort
B3: This block has almost no pace targets — on purpose. It is run by FEEL.
B5: Effort guide
B6: Easy / Long run | C6: Conversational. You can speak in full sentences. Nose-breathing when possible. Most people run this too fast.
B7: Aerobic strides | C7: 'Roughly 5K effort' — controlled and quick, not a sprint. Doesn't need to be exact.
B8: Hill blasts | C8: ~95-98% effort but FORM-controlled. Fast, fluent, relaxed — never straining/eyeballs-out.
B9: Everything else | C9: Rest or easy. There is no tempo, threshold, or interval pacing in this block. Those come in the Super Base.
B11: Why no pace table?
B12: John coaches beginners to run by feel and 'understand their body' — that's an explicit goal of the Foundation stage, not an afterthought.
B13: Prescribing paces to a shuffler just makes them shuffle faster and get injured. Form and feel come first; pace takes care of itself later.
B14: You WILL see easy-run pace drift faster at the same effort as economy improves. Let it happen — don't chase it.
B15: When you reach the Super Base workbook, that's where a pace anchor (T pace) gets introduced.

Sheet Coach Philosophy
B2: Coach Philosophy — this stage
B3: Grounded in John Starrett's 'The Stablemaster Speaks'. Sources cited so you can verify.
B5: Principle | C5: What it means (+ source)
B6: 1. You are a 'shuffler' first. | C6: Newer/slower runners are hip-flexor and quad dominant with a shuffly stride, which loads the calves/Achilles/knees and causes injury. Fixing this comes before anything else. (Ep. 049 'The Method Behind the Madness', ~'you're a shuffler'; YouTube 'Coaching Beginners to Olympians', 'hip flex dominant ... shuffly stride'.)
B7: 2. Too much too soon = injury. | C7: Beginners get medial tibial stress syndrome / shin splints from running too fast, too far, or in the wrong shoes. Foundation exists to prevent exactly this. (YouTube interview, 'The Foundation phase' section; Ep. 044.)
B8: 3. Foundation target: 3x65 + 1x90 easy. | C8: 'They need to be able to run 90 minutes easy and 3x65 easy' before moving on. No tempo, no speed. (Ep. 044 'Stazza's Stable Masterclass', ~line 17870-17871; YouTube interview.)
B9: 4. Progress 5-10 min/week, by feel. | C9: 'They would progress maybe five or 10 minutes each week depending on their injury history, their age, and their background and what time they have available.' Repeat weeks freely. (YouTube interview, Foundation section.)
B10: 5. Start de-conditioned runners very low. | C10: John started one runner (Akash) at 35-min easy runs while managing medial tibial stress, then built up. (Ep. 044, ~line 21878-21879.)
B11: 6. Slower runners get an ELONGATED block. | C11: 'It's definitely going to need to be an elongated pre super base ... rather than going through the seven weeks it normally takes.' Time is on your side. (Ep. 051 'Zeus Spoke I Listened', ~line 27380-27381.)
B12: 7. Four runs beats three. | C12: 'If somebody's running three times a week, I generally give them a little nudge ... there's an advantage to [four].' Three tends to maintain; four lets you progress with manageable injury risk. (YouTube interview.)
B13: 8. Pre-Super Base = rewire the stride. | C13: Goal: change from hip-flexor dominant to glute dominant, increasing hip extension, power and stride length — done automatically through running, NOT through gym strength work. (Ep. 044 ~17872; Ep. 049 ~25926-25929; YouTube interview 'Pre-Super Base'.)
B14: 9. Hill blasts are the best bang for buck. | C14: 8-sec blasts, shallow hill, 2:30 walk recovery (CP energy system), mantra 'tall/relaxed/piston/pop'. Reps 4>6>8. Improves running economy — 'the marathon's mainly about running economy'. (Ep. 044 ~17877-17939; Ep. 049 ~25958-26021; YouTube interview 'Hill blasts explained'.)
B15: 10. Aerobic strides pair with hill blasts. | C15: 3x5x20s>30s>40s at ~5K effort, generous recovery; then a 2>3>4>5 min add-on. The two sessions work synergistically; economy gains transfer into easy running. (Ep. 044 ~17914-17945; Ep. 049 ~25932-25957; YouTube 'Aerobic strides progression'.)
B16: 11. Long run stays at 90 min here. | C16: 'Just 90 minutes easy. There's no tempo in it. It doesn't go any longer than that.' It only starts carrying work in the Super Base. (YouTube interview, ~line 28193-28195.)
... B20: Note on sourcing | C20: Auto-transcribed audio: John's surname appears as 'Stewart/Starrett', paces are given in min/km in some episodes (converted here where noted), and line numbers reference the compiled transcript file. This tab = what John actually says. The Calendar's expanded durations (10+8 wks) are a reasonable extrapolation of his 'elongated for slower runners' guidance, not a fixed program he published.

Sheet Progress Log
B2: Progress Log
B3: One row per day. Dates derive from the Start Date. Mark Status — the Dashboard updates.
B4: Date | C4: Wk | D4: Phase | E4: Day | F4: Planned run | G4: Status | H4: Actual min | I4: Felt (1-10) | J4: Notes
B5: =Inputs!$C$15+0 -> 46237 | C5: 1 | D5: Pre-Foundation 1 | E5: Mon | F5: Rest or 20 min walk
B6: =Inputs!$C$15+1 -> 46238 | C6: 1 | D6: Pre-Foundation 1 | E6: Tue | F6: Jog-walk 25 min (e.g. 3 min jog / 1 min walk)
B7: =Inputs!$C$15+2 -> 46239 | C7: 1 | D7: Pre-Foundation 1 | E7: Wed | F7: Jog-walk 25 min easy
B8: =Inputs!$C$15+3 -> 46240 | C8: 1 | D8: Pre-Foundation 1 | E8: Thu | F8: Rest or 20 min walk
B9: =Inputs!$C$15+4 -> 46241 | C9: 1 | D9: Pre-Foundation 1 | E9: Fri | F9: Jog-walk 25 min easy
B10: =Inputs!$C$15+5 -> 46242 | C10: 1 | D10: Pre-Foundation 1 | E10: Sat | F10: Jog-walk 30 min easy
B11: =Inputs!$C$15+6 -> 46243 | C11: 1 | D11: Pre-Foundation 1 | E11: Sun | F11: Rest
B12: =Inputs!$C$15+7 -> 46244 | C12: 2 | D12: Pre-Foundation 2 | E12: Mon | F12: Rest or 20 min walk
B13: =Inputs!$C$15+8 -> 46245 | C13: 2 | D13: Pre-Foundation 2 | E13: Tue | F13: Easy run 30 min (walk breaks as needed)
B14: =Inputs!$C$15+9 -> 46246 | C14: 2 | D14: Pre-Foundation 2 | E14: Wed | F14: Easy run 30 min
B15: =Inputs!$C$15+10 -> 46247 | C15: 2 | D15: Pre-Foundation 2 | E15: Thu | F15: Rest or 20 min walk
B16: =Inputs!$C$15+11 -> 46248 | C16: 2 | D16: Pre-Foundation 2 | E16: Fri | F16: Easy run 30 min
B17: =Inputs!$C$15+12 -> 46249 | C17: 2 | D17: Pre-Foundation 2 | E17: Sat | F17: Easy run 35 min
B18: =Inputs!$C$15+13 -> 46250 | C18: 2 | D18: Pre-Foundation 2 | E18: Sun | F18: Rest
B19: =Inputs!$C$15+14 -> 46251 | C19: 3 | D19: Foundation 1 | E19: Mon | F19: Rest / cross-train
B20: =Inputs!$C$15+15 -> 46252 | C20: 3 | D20: Foundation 1 | E20: Tue | F20: Easy 35 min
B21: =Inputs!$C$15+16 -> 46253 | C21: 3 | D21: Foundation 1 | E21: Wed | F21: Easy 35 min
B22: =Inputs!$C$15+17 -> 46254 | C22: 3 | D22: Foundation 1 | E22: Thu | F22: Rest / cross-train
B23: =Inputs!$C$15+18 -> 46255 | C23: 3 | D23: Foundation 1 | E23: Fri | F23: Easy 35 min
B24: =Inputs!$C$15+19 -> 46256 | C24: 3 | D24: Foundation 1 | E24: Sat | F24: Long run 40 min easy (no tempo)
B25: =Inputs!$C$15+20 -> 46257 | C25: 3 | D25: Foundation 1 | E25: Sun | F25: Rest
B26: =Inputs!$C$15+21 -> 46258 | C26: 4 | D26: Foundation 2 | E26: Mon | F26: Rest / cross-train
B27: =Inputs!$C$15+22 -> 46259 | C27: 4 | D27: Foundation 2 | E27: Tue | F27: Easy 40 min
B28: =Inputs!$C$15+23 -> 46260 | C28: 4 | D28: Foundation 2 | E28: Wed | F28: Easy 40 min
B29: =Inputs!$C$15+24 -> 46261 | C29: 4 | D29: Foundation 2 | E29: Thu | F29: Rest / cross-train
B30: =Inputs!$C$15+25 -> 46262 | C30: 4 | D30: Foundation 2 | E30: Fri | F30: Easy 40 min
B31: =Inputs!$C$15+26 -> 46263 | C31: 4 | D31: Foundation 2 | E31: Sat | F31: Long run 45 min easy (no tempo)
B32: =Inputs!$C$15+27 -> 46264 | C32: 4 | D32: Foundation 2 | E32: Sun | F32: Rest
B33: =Inputs!$C$15+28 -> 46265 | C33: 5 | D33: Foundation 3 | E33: Mon | F33: Rest / cross-train
B34: =Inputs!$C$15+29 -> 46266 | C34: 5 | D34: Foundation 3 | E34: Tue | F34: Easy 45 min
B35: =Inputs!$C$15+30 -> 46267 | C35: 5 | D35: Foundation 3 | E35: Wed | F35: Easy 40 min
B36: =Inputs!$C$15+31 -> 46268 | C36: 5 | D36: Foundation 3 | E36: Thu | F36: Rest / cross-train
B37: =Inputs!$C$15+32 -> 46269 | C37: 5 | D37: Foundation 3 | E37: Fri | F37: Easy 45 min
B38: =Inputs!$C$15+33 -> 46270 | C38: 5 | D38: Foundation 3 | E38: Sat | F38: Long run 50 min easy (no tempo)
B39: =Inputs!$C$15+34 -> 46271 | C39: 5 | D39: Foundation 3 | E39: Sun | F39: Rest
B40: =Inputs!$C$15+35 -> 46272 | C40: 6 | D40: Foundation 4 | E40: Mon | F40: Rest / cross-train
B41: =Inputs!$C$15+36 -> 46273 | C41: 6 | D41: Foundation 4 | E41: Tue | F41: Easy 50 min
...
