Workbook
Name EasyMinOvr: Inputs!$C$11
Name EasySecOvr: Inputs!$C$12
Name EndDate: Inputs!$C$17
Name RaceDate: Inputs!$C$16
Name StartDate: Inputs!$C$15
Name T_min: Inputs!$C$9
Name T_sec: Inputs!$C$10

Sheet Cover
B2: John Starrett's Super Base Running Training
B3: The Stablemaster's blueprint — Super Base phase, 14 weeks + taper + recovery
B6: Workbook | F6: Phase Roadmap
B7: Version | C7: 1.1.1 | F7: Foundation | G7: ○ Future
B8: Build date | C8: July 19, 2026 | F8: Pre-Super Base | G8: ○ Future
B9: Phase implemented | C9: ✓ Super Base | F9: Super Base | G9: ● v1.1.1 (implemented)
B10: Structure | C10: 14 wk Super Base + 1 wk taper/race + 1 wk recovery | F10: Marathon Bridge | G10: ○ Future
B11: Weekly rhythm | C11: 4 runs (Tue/Wed/Fri/Sat) + 3 rest days | F11: Marathon Specific | G11: ○ Future
B12: Anchor pace | C12: T (1-hour tempo effort) | F12: Taper | G12: ○ Future (full block)
F13: Recovery | G13: ○ Future (full block)
B15: Coach Philosophy — the short version
B16: • Training is putting money in the bank. Racing is spending it. Race for purpose.
B17: • Stimulate, don't annihilate. Finish every session feeling you could do 1-2 more reps.
B18: • The Super Base is the foundation — the hole in the ground, not the paint on the wall.
B19: • Effort > pace. Run by feel. T is what you could hold for a 1-hour race today.
B20: • The Endurance Spine is the cement that mortises the interstices. Never race it.
B21: • Down the V, get 5 sec/mi faster each session. Up the V, HOLD the faster pace.
B22: • Rest is training. Three rest days a week is a feature, not a bug.
B24: Navigate
B25: Inputs | C25: → | D25: Dashboard | E25: → | F25: SB Calendar | G25: →
B26: Workout Library | C26: → | D26: Paces & Race Predictor | E26: → | F26: Coach Philosophy | G26: →
B27: Progress Log | C27: →

Sheet Inputs
B2: Inputs
B3: Yellow cells are yours to edit. Everything else — dates, paces, dashboard KPIs, predictions — derives from these.
B5: Athlete | E5: How this workbook flows
B6: Name | C6: Bjorn | E6: 1. Inputs — Set your T pace and start date here. Everything else derives from these.
E7: 2. Dashboard — See where you are today: current week, phase, and workout.
B8: Pace | E8: 3. SB Calendar — The full 16-week plan laid out day-by-day.
B9: T pace — minutes | C9: 8 | E9: 4. Workout Library — Detail cards for every session type — read before your first hard workout.
B10: T pace — seconds | C10: 0 | E10: 5. Paces & Race Predictor — Auto-computed paces plus 5K/10K/HM/Marathon predictions.
B11: Easy pace override — minutes | E11: 6. Coach Philosophy — The 12 principles this plan runs on.
B12: Easy pace override — seconds | E12: 7. Progress Log — Track every day — planned vs actual. Dashboard reads from here.
B14: Dates
B15: Start date (Monday of Week 1) | C15: 46237
B16: Race date (Saturday of Week 15) — derived | C16: =C15+103 -> 46340
B17: Plan end date (Sunday of Week 16) — derived | C17: =C15+111 -> 46348
B19: Plan structure
B20: Total duration | C20: 16 weeks
B21: Super Base | C21: 14 weeks (John's canonical length)
B22: Taper + race week | C22: 1 week
B23: Recovery | C23: 1 week
B24: Runs per week | C24: 4 (Tue/Wed/Fri/Sat)
B25: Weekly workouts | C25: 1 midweek session + 1 endurance spine

Sheet Dashboard
B2: Dashboard
B3: Where you are today. Refreshes from Inputs and Progress Log.
B5: CURRENT WEEK | D5: CURRENT PHASE | F5: COMPLETION | I5: Wk | J5: Total min | K5: Sessions
B6: =IF(TODAY()<StartDate,0,MIN(16,INT((TODAY()-StartDate)/7)+1)) -> 0 | D6: =IF(TODAY()<StartDate,"Not started",IF(TODAY()>EndDate,"Complete",IF(INT((TODAY()-StartDate)/7)+1<=4,"Super Base — Tempo Build",IF(INT((TODAY()-StartDate)/7)+1=5,"Super Base — Transition to V",IF(INT((TODAY()-StartDate)/7)+1<=10,"Super Base — V Descent",IF(INT((TODAY()-StartDate)/7)+1<=14,"Super Base — V Ascent → Peak",IF(INT((TODAY()-StartDate)/7)+1=15,"Race Week (taper + race)","Recovery"))))))) -> Not started | F6: =IF(TODAY()<StartDate,0,MIN(1,(TODAY()-StartDate)/(16*7))) -> 0 | I6: 1 | J6: 265 | K6: 1
I7: 2 | J7: 290 | K7: 1
B8: T PACE (input) | D8: RACE DATE | F8: DAYS TO RACE | I8: 3 | J8: 305 | K8: 1
B9: =TEXT(INT(((T_min*60+T_sec))/60),"0")&":"&TEXT(MOD((T_min*60+T_sec),60),"00") -> 8:00 | D9: =TEXT(RaceDate,"ddd, mmm d") -> Sat, Nov 14 | F9: =IF(TODAY()>RaceDate,"Completed",RaceDate-TODAY()) -> 114 | I9: 4 | J9: 290 | K9: 1
I10: 5 | J10: 300 | K10: 1
B11: This week | I11: 6 | J11: 326 | K11: 1
B12: WED — SESSION | C12: =IF(TODAY()<StartDate,"Not started",IF(INT((TODAY()-StartDate)/7)+1>16,"Plan complete",INDEX('SB Calendar'!$G$4:$G$19,INT((TODAY()-StartDate)/7)+1))) -> Not started | I12: 7 | J12: 312 | K12: 1
B13: SAT — ENDURANCE SPINE | C13: =IF(TODAY()<StartDate,"Not started",IF(INT((TODAY()-StartDate)/7)+1>16,"Plan complete",INDEX('SB Calendar'!$J$4:$J$19,INT((TODAY()-StartDate)/7)+1))) -> Not started | I13: 8 | J13: 312 | K13: 1
I14: 9 | J14: 323 | K14: 1
B15: Race predictor (based on T pace) | I15: 10 | J15: 284 | K15: 1
B16: Distance | C16: Race pace | D16: Predicted time | E16: Notes | I16: 11 | J16: 303 | K16: 1
B17: 5K | C17: =TEXT(INT((((T_min*60+T_sec)+-25))/60),"0")&":"&TEXT(MOD(((T_min*60+T_sec)+-25),60),"00")&"/mi" -> 7:35/mi | D17: =IF((3.10686*((T_min*60+T_sec)+-25))>=3600,INT((3.10686*((T_min*60+T_sec)+-25))/3600)&":"&TEXT(INT(MOD((3.10686*((T_min*60+T_sec)+-25)),3600)/60),"00")&":"&TEXT(MOD((3.10686*((T_min*60+T_sec)+-25)),60),"00"),INT((3.10686*((T_min*60+T_sec)+-25))/60)&":"&TEXT(MOD((3.10686*((T_min*60+T_sec)+-25)),60),"00")) -> 23:34 | E17: Fast; ~25-30 sec/mi under T | I17: 12 | J17: 323 | K17: 1
B18: 10K | C18: =TEXT(INT((((T_min*60+T_sec)+-12))/60),"0")&":"&TEXT(MOD(((T_min*60+T_sec)+-12),60),"00")&"/mi" -> 7:48/mi | D18: =IF((6.21371*((T_min*60+T_sec)+-12))>=3600,INT((6.21371*((T_min*60+T_sec)+-12))/3600)&":"&TEXT(INT(MOD((6.21371*((T_min*60+T_sec)+-12)),3600)/60),"00")&":"&TEXT(MOD((6.21371*((T_min*60+T_sec)+-12)),60),"00"),INT((6.21371*((T_min*60+T_sec)+-12))/60)&":"&TEXT(MOD((6.21371*((T_min*60+T_sec)+-12)),60),"00")) -> 48:28 | E18: Between 5K and T; ~12 sec/mi under T | I18: 13 | J18: 293 | K18: 1
B19: Half Marathon | C19: =TEXT(INT((((T_min*60+T_sec)+7))/60),"0")&":"&TEXT(MOD(((T_min*60+T_sec)+7),60),"00")&"/mi" -> 8:07/mi | D19: =IF((13.10938*((T_min*60+T_sec)+7))>=3600,INT((13.10938*((T_min*60+T_sec)+7))/3600)&":"&TEXT(INT(MOD((13.10938*((T_min*60+T_sec)+7)),3600)/60),"00")&":"&TEXT(MOD((13.10938*((T_min*60+T_sec)+7)),60),"00"),INT((13.10938*((T_min*60+T_sec)+7))/60)&":"&TEXT(MOD((13.10938*((T_min*60+T_sec)+7)),60),"00")) -> 1:46:24 | E19: ≈ T + 7 sec/mi (10-mile is ~7 sec/mi under HM) | I19: 14 | J19: 314 | K19: 1
B20: Marathon | C20: =TEXT(INT((((T_min*60+T_sec)+27))/60),"0")&":"&TEXT(MOD(((T_min*60+T_sec)+27),60),"00")&"/mi" -> 8:27/mi | D20: =IF((26.21876*((T_min*60+T_sec)+27))>=3600,INT((26.21876*((T_min*60+T_sec)+27))/3600)&":"&TEXT(INT(MOD((26.21876*((T_min*60+T_sec)+27)),3600)/60),"00")&":"&TEXT(MOD((26.21876*((T_min*60+T_sec)+27)),60),"00"),INT((26.21876*((T_min*60+T_sec)+27))/60)&":"&TEXT(MOD((26.21876*((T_min*60+T_sec)+27)),60),"00")) -> 3:41:33 | E20: HM pace + 20 sec/mi per Stazza | I20: 15 | J20: 220 | K20: 1
I21: 16 | J21: 160 | K21: 0
I44: Status | J44: Count
I45: Completed | J45: =COUNTIF('Progress Log'!G:G,"Completed") -> 0
I46: Modified | J46: =COUNTIF('Progress Log'!G:G,"Modified") -> 0
I47: Missed | J47: =COUNTIF('Progress Log'!G:G,"Missed") -> 0
I48: Planned | J48: =COUNTIF('Progress Log'!G:G,"Planned") -> 0

Sheet SB Calendar
B2: Super Base Calendar — 14 weeks + 1 taper + 1 recovery
B3: Wk | C3: Week of | D3: Phase | E3: Mon | F3: Tue | G3: Wed — SESSION | H3: Thu | I3: Fri | J3: Sat — ENDURANCE SPINE | K3: Sun | L3: Weekly notes
B4: 1 | C4: =StartDate+(1-1)*7 -> 46237 | D4: Tempo Build 1 | E4: Rest / cross-train | F4: Easy 60 min @ T+60 | G4: 20 min WU / 20 min @ T / 20 min CD | H4: Rest / cross-train | I4: Easy 60 min @ T+60 | J4: 30 min easy / 40 min @ T+20 / 30 min easy | K4: Rest | L4: Baseline week. Finish the 20-min tempo feeling you could hold it another 30-40 min. Endurance spine tempo pace = 20 sec/mi slower than midweek tempo.
B5: 2 | C5: =StartDate+(2-1)*7 -> 46244 | D5: Tempo Build 2 | E5: Rest / cross-train | F5: Easy 60 min @ T+60 | G5: 20 min easy / 20 min @ T / 5 min easy / 10 min @ T / 20 min easy | H5: Rest / cross-train | I5: Easy 60 min @ T+60 | J5: 30 min easy / 50 min @ T+20 / 30 min easy | K5: Rest | L5: Adding 10 min of tempo. Endurance spine to 50 min. Same paces as W1.
B6: 3 | C6: =StartDate+(3-1)*7 -> 46251 | D6: Tempo Build 3 | E6: Rest / cross-train | F6: Easy 60 min @ T+60 | G6: 20 min easy / 20 min @ T / 5 min easy / 15 min @ T / 20 min easy | H6: Rest / cross-train | I6: Easy 60 min @ T+60 | J6: 30 min easy / 60 min @ T+20 / 30 min easy | K6: Rest | L6: 35 min of tempo in-session. Endurance spine caps first cycle at 60 min @ T+20.
B7: 4 | C7: =StartDate+(4-1)*7 -> 46258 | D7: Tempo Build 4 | E7: Rest / cross-train | F7: Easy 60 min @ T+60 | G7: 20 min easy / 2x 20 min @ T off 5 min easy / 20 min easy | H7: Rest / cross-train | I7: Easy 60 min @ T+60 | J7: 30 min easy / 40 min @ T+15 / 30 min easy | K7: Rest | L7: Peak of tempo build: 2x20 @ T. Endurance spine peels back to 40 min but 5 sec/mi faster (T+15). Cycle 2 begins.
B8: 5 | C8: =StartDate+(5-1)*7 -> 46265 | D8: Transition into V | E8: Rest / cross-train | F8: Easy 60 min @ T+60 | G8: 20 min WU / 20 min @ T / 5 easy / 10 min @ T-5 / 5 easy / 2x 5 min @ T-10 off 3 min / 20 min CD | H8: Rest / cross-train | I8: Easy 60 min @ T+60 | J8: 30 min easy / 50 min @ T+15 / 30 min easy | K8: Rest | L8: Bridge session into the V — first taste of T-10.
B9: 6 | C9: =StartDate+(6-1)*7 -> 46272 | D9: Descent 1: Precipice | E9: Rest / cross-train | F9: Easy 60 min @ T+60 | G9: 20 min WU / 8x 5 min @ T-10 off 3 min jog / 20 min CD | H9: Rest / cross-train | I9: Easy 60 min @ T+60 | J9: 30 min easy / 60 min @ T+15 / 30 min easy | K9: Rest | L9: The precipice of the V-shaped valley of death. 40 min of work at 10-mile pace.
B10: 7 | C10: =StartDate+(7-1)*7 -> 46279 | D10: Descent 2 | E10: Rest / cross-train | F10: Easy 60 min @ T+60 | G10: 20 min WU / 10x 4 min @ T-15 off 3 min jog / 20 min CD | H10: Rest / cross-train | I10: Easy 60 min @ T+60 | J10: 30 min easy / 40 min @ T+10 / 30 min easy | K10: Rest | L10: Same volume (40 min), shorter reps, 5 sec/mi faster.
B11: 8 | C11: =StartDate+(8-1)*7 -> 46286 | D11: Descent 3 | E11: Rest / cross-train | F11: Easy 60 min @ T+60 | G11: 20 min WU / 10x 3 min @ T-20 off 3 min jog / 20 min CD | H11: Rest / cross-train | I11: Easy 60 min @ T+60 | J11: 30 min easy / 50 min @ T+10 / 30 min easy | K11: Rest | L11: 10x3 at 10K effort. Volume drops to 30 min.
B12: 9 | C12: =StartDate+(9-1)*7 -> 46293 | D12: Descent 4 | E12: Rest / cross-train | F12: Easy 60 min @ T+60 | G12: 20 min WU / 15x 2 min @ T-25 off 2 min jog / 20 min CD | H12: Rest / cross-train | I12: Easy 60 min @ T+60 | J12: 30 min easy / 60 min @ T+10 / 30 min easy | K12: Rest | L12: 15x2 — approaching 5K blend. Recoveries tighten to 2 min.
B13: 10 | C13: =StartDate+(10-1)*7 -> 46300 | D13: Descent 5: Bottom of V | E13: Rest / cross-train | F13: Easy 60 min @ T+60 | G13: 20 min WU / 20x 1 min @ T-30 (5K pace) off 1 min jog / 20 min CD | H13: Rest / cross-train | I13: Easy 60 min @ T+60 | J13: 30 min easy / 40 min @ T+5 / 30 min easy | K13: Rest | L13: Bottom of the V. 5K pace touch — safe because reps are only 1 min.
B14: 11 | C14: =StartDate+(11-1)*7 -> 46307 | D14: Ascent 1 | E14: Rest / cross-train | F14: Easy 60 min @ T+60 | G14: 20 min WU / 15x 2 min @ T-25 off 2 min jog / 20 min CD | H14: Rest / cross-train | I14: Easy 60 min @ T+60 | J14: 30 min easy / 50 min @ T+5 / 30 min easy | K14: Rest | L14: Ascent starts. Same 15x2 shape as Wk 9, same pace — familiar territory after touching T-30 last week. Establishes the pace we'll HOLD into Wk 12.
B15: 12 | C15: =StartDate+(12-1)*7 -> 46314 | D15: Ascent 2 | E15: Rest / cross-train | F15: Easy 60 min @ T+60 | G15: 20 min WU / 10x 3 min @ T-25 off 2 min jog / 20 min CD | H15: Rest / cross-train | I15: Easy 60 min @ T+60 | J15: 30 min easy / 60 min @ T+5 / 30 min easy | K15: Rest | L15: Same 10x3 shape as Wk 8 but HOLDING T-25 pace instead of slowing to T-20. This is John's exact ascent quote in action: 'when you do the 10x3, instead of slowing down 3 sec/km, you hold the pace.'
B16: 13 | C16: =StartDate+(13-1)*7 -> 46321 | D16: Ascent 3 | E16: Rest / cross-train | F16: Easy 60 min @ T+60 | G16: 20 min WU / 10x 4 min @ T-20 off 2 min jog / 20 min CD | H16: Rest / cross-train | I16: Easy 60 min @ T+60 | J16: 30 min easy / 40 min @ T / 30 min easy | K16: Rest | L16: Same 10x4 shape as Wk 7 but 5 sec/mi faster (T-20 vs T-15). Endurance spine peels to 40 min but at your original 20-min tempo pace — the pace transformation is showing.
B17: 14 | C17: =StartDate+(14-1)*7 -> 46328 | D17: Peak week 🏔 — Ascent 4 | E17: Rest / cross-train | F17: Easy 60 min @ T+60 | G17: 20 min WU / 8x 5 min @ T-15 off 2 min jog / 20 min CD | H17: Rest / cross-train | I17: Easy 45 min @ T+60 | J17: 30 min easy / 60 min @ T / 30 min easy | K17: Rest | L17: THE MILESTONE. Same 8x5 shape as the Wk 6 precipice but 5 sec/mi FASTER on tighter recovery (2 min vs 3 min). Endurance spine hits 60 min @ T — your 60-min tempo equals your original 20-min tempo pace. Super Base fitness proven.
B18: 15 | C18: =StartDate+(15-1)*7 -> 46335 | D18: 🏁 Race Week (taper + race) | E18: Rest | F18: 20 min WU / 4x 90s @ T off 90s easy / 20 min CD | G18: Rest or easy 30 min | H18: Rest | I18: Easy 20 min + 4x 20s strides | J18: 🏁 HALF MARATHON — race by effort. Warmup 15-20 min easy + drills + 4 strides. Target: HM pace ≈ T+7 sec/mi (or below if the day is on). Cool down 10-15 min. | K18: Rest | L18: Race week. Light sharpener Tue keeps neuromuscular system alive. Race Sat. Coming off a full Super Base, John's coincidence says nearly everyone PBs here.
B19: 16 | C19: =StartDate+(16-1)*7 -> 46342 | D19: Recovery | E19: Rest — walk 30 min | F19: Rest or easy 30 min walk | G19: Easy 30 min (by feel, no watch) | H19: Rest | I19: Easy 40 min | J19: Easy 60 min by feel — no tempo, no target pace | K19: Rest | L19: Full recovery. Zero quality work. John's guidance: rest is when fitness locks in. Do NOT sneak a workout.

Sheet Workout Library
B2: Workout Library
B3: The Stazza sessions used in this Super Base. Read the card before you run the workout.
B5: Easy Run
B6: Purpose | C6: Aerobic development, capillarization, musculoskeletal accumulation. The bulk of your weekly volume. If it's not the Wednesday session or the Saturday endurance spine, it's easy.
B7: Adaptation | C7: Increased mitochondrial density, capillary bed expansion, tendon/ligament adaptation. Fat-oxidation efficiency.
B8: Warm-up | C8: None required — start easy and stay easy.
B9: Main Set | C9: 60 min continuous @ T+60 sec/mi (or slower). By feel: conversation pace, nose-breathing when possible.
B10: Cool-down | C10: Walk 5 min. Optional 4x 20s strides on Fri only.
B11: Coach Notes | C11: Elite runners run easy runs slower than most amateurs think they should. If your Saturday endurance spine feels flat, your easy runs are too fast.
B12: Common Mistakes | C12: Running easy runs at moderate pace ('the grey zone'). Racing Strava segments. Turning easy runs into extra sessions.
B13: Progression Rules | C13: Volume can grow 5-10 min every 3-4 weeks. Pace should NOT progress — if easy pace is dropping without effort dropping, you're recovering less than you think.
B15: Recovery Run
B16: Purpose | C16: Post-session or post-race circulation. Not a fitness session — a recovery tool.
B17: Adaptation | C17: None targeted. Blood flow, lymphatic drainage, mental reset.
B18: Warm-up | C18: Walk 3-5 min if legs are stiff.
B19: Main Set | C19: 30-45 min continuous @ T+90 sec/mi. Slower is better. Watch off if possible.
B20: Cool-down | C20: Walk 5 min. Foam roll if tight.
B21: Coach Notes | C21: The purpose is to bring nothing home from the previous day. If you finish a recovery run breathing harder than you started, it wasn't a recovery run.
B22: Common Mistakes | C22: Treating it as an easy run. Running it too far. Adding strides.
B23: Progression Rules | C23: None — recovery runs stay recovery. If you feel great on recovery day, that's not permission to push.
B25: Aerobic Strides
B26: Purpose | C26: Neuromuscular sharpness without accumulating fatigue. Reminds the body what fast feels like between the two weekly key sessions.
B27: Adaptation | C27: Motor unit recruitment, running economy, form efficiency at speed.
B28: Warm-up | C28: Slot into the tail end of a Friday easy run — you're already warm.
B29: Main Set | C29: 4x 20 seconds at ~mile-race effort (NOT sprinting). 60-90 sec walk/jog recovery between.
B30: Cool-down | C30: Walk 3-5 min after last stride.
B31: Coach Notes | C31: Strides are 'controlled fast', not eyeballs-out. Should feel effortless and mechanically clean. If you're straining, you're going too hard.
B32: Common Mistakes | C32: Sprinting. Doing them tired. Doing them the day before a session.
B33: Progression Rules | C33: Duration stays at 20s. Can increase quantity to 6x once the plan is beyond 12 weeks in. Never before a race.
B35: Tempo (T pace)
B36: Purpose | C36: The foundation of the whole Super Base. Introduces sustained work at 1-hour race effort — the anchor for every other session.
B37: Adaptation | C37: Lactate clearance at moderate-hard effort. Aerobic ceiling. Sub-threshold economy.
B38: Warm-up | C38: 20 min easy jog. Optional 2-4x strides if legs feel heavy.
B39: Main Set | C39: Weeks 1-4 progression: 20 min @ T → 20+10 @ T → 20+15 @ T → 2x20 @ T (5 min easy between).
B40: Cool-down | C40: 20 min easy jog.
B41: Coach Notes | C41: 'T' is what you could hold for a ONE-HOUR race today. Not lactate threshold. Not Daniels V-dot. Effort-based. Finish feeling you could hold it another 30-40 min.
B42: Common Mistakes | C42: Running T pace by heart rate. Racing the tempo. Chasing a specific pace target instead of running the correct effort.
B43: Progression Rules | C43: Volume ramps to 40 min at T before V descent begins. Don't add more T volume once V descent starts.
B45: V Descent Session
B46: Purpose | C46: Increase pace by shortening reps. Take the T-pace fitness and sharpen it toward 5K over 5 weeks.
...

Sheet Paces & Race Predictor
B2: Paces & Race Predictor
B3: All paces derive from T on the Inputs sheet. Change T there — every value here updates.
B5: Pace Reference (min/mi)
B6: Label | C6: Purpose | D6: Offset (sec/mi) | E6: Pace min:sec
B7: T-30 | C7: 5K effort — bottom of V (20x1 min) | D7: -30 | E7: =TEXT(INT((((T_min*60+T_sec)+-30))/60),"0")&":"&TEXT(MOD(((T_min*60+T_sec)+-30),60),"00") -> 7:30
B8: T-25 | C8: 5K/3K blend — 15x2 min pace | D8: -25 | E8: =TEXT(INT((((T_min*60+T_sec)+-25))/60),"0")&":"&TEXT(MOD(((T_min*60+T_sec)+-25),60),"00") -> 7:35
B9: T-20 | C9: 10K effort — 10x3 min pace | D9: -20 | E9: =TEXT(INT((((T_min*60+T_sec)+-20))/60),"0")&":"&TEXT(MOD(((T_min*60+T_sec)+-20),60),"00") -> 7:40
B10: T-15 | C10: 10-mile effort — 10x4 min pace | D10: -15 | E10: =TEXT(INT((((T_min*60+T_sec)+-15))/60),"0")&":"&TEXT(MOD(((T_min*60+T_sec)+-15),60),"00") -> 7:45
B11: T-10 | C11: 10-mile / threshold — 8x5 min pace | D11: -10 | E11: =TEXT(INT((((T_min*60+T_sec)+-10))/60),"0")&":"&TEXT(MOD(((T_min*60+T_sec)+-10),60),"00") -> 7:50
B12: T-5 | C12: Threshold — early tempo add-ons | D12: -5 | E12: =TEXT(INT((((T_min*60+T_sec)+-5))/60),"0")&":"&TEXT(MOD(((T_min*60+T_sec)+-5),60),"00") -> 7:55
B13: T | C13: 1-HOUR TEMPO EFFORT (input, ≈ HM+7) | D13: 0 | E13: =TEXT(INT((((T_min*60+T_sec)+0))/60),"0")&":"&TEXT(MOD(((T_min*60+T_sec)+0),60),"00") -> 8:00
B14: T+5 | C14: Endurance Spine — cycle 4 | D14: 5 | E14: =TEXT(INT((((T_min*60+T_sec)+5))/60),"0")&":"&TEXT(MOD(((T_min*60+T_sec)+5),60),"00") -> 8:05
B15: T+10 | C15: Endurance Spine — cycle 3 | D15: 10 | E15: =TEXT(INT((((T_min*60+T_sec)+10))/60),"0")&":"&TEXT(MOD(((T_min*60+T_sec)+10),60),"00") -> 8:10
B16: T+15 | C16: Endurance Spine — cycle 2 | D16: 15 | E16: =TEXT(INT((((T_min*60+T_sec)+15))/60),"0")&":"&TEXT(MOD(((T_min*60+T_sec)+15),60),"00") -> 8:15
B17: T+20 | C17: Endurance Spine — cycle 1 (start) | D17: 20 | E17: =TEXT(INT((((T_min*60+T_sec)+20))/60),"0")&":"&TEXT(MOD(((T_min*60+T_sec)+20),60),"00") -> 8:20
B18: T+40 | C18: Structural run tempo pace (80-90 min) | D18: 40 | E18: =TEXT(INT((((T_min*60+T_sec)+40))/60),"0")&":"&TEXT(MOD(((T_min*60+T_sec)+40),60),"00") -> 8:40
B19: T+60 | C19: Easy run pace (guide — run by feel) | D19: 60 | E19: =TEXT(INT((((T_min*60+T_sec)+60))/60),"0")&":"&TEXT(MOD(((T_min*60+T_sec)+60),60),"00") -> 9:00
B20: T+90 | C20: Recovery pace | D20: 90 | E20: =TEXT(INT((((T_min*60+T_sec)+90))/60),"0")&":"&TEXT(MOD(((T_min*60+T_sec)+90),60),"00") -> 9:30
B23: Race Predictor
B24: Rough predictions based on your T pace. Assumes race-day conditions, adequate taper, and executed pacing.
B25: Distance | C25: Distance (mi) | D25: Race pace | E25: Predicted time
B26: 5K | C26: 3.10686 | D26: =TEXT(INT((((T_min*60+T_sec)+-25))/60),"0")&":"&TEXT(MOD(((T_min*60+T_sec)+-25),60),"00")&"/mi" -> 7:35/mi | E26: =IF((3.10686*((T_min*60+T_sec)+-25))>=3600,INT((3.10686*((T_min*60+T_sec)+-25))/3600)&":"&TEXT(INT(MOD((3.10686*((T_min*60+T_sec)+-25)),3600)/60),"00")&":"&TEXT(MOD((3.10686*((T_min*60+T_sec)+-25)),60),"00"),INT((3.10686*((T_min*60+T_sec)+-25))/60)&":"&TEXT(MOD((3.10686*((T_min*60+T_sec)+-25)),60),"00")) -> 23:34
B27: 10K | C27: 6.21371 | D27: =TEXT(INT((((T_min*60+T_sec)+-12))/60),"0")&":"&TEXT(MOD(((T_min*60+T_sec)+-12),60),"00")&"/mi" -> 7:48/mi | E27: =IF((6.21371*((T_min*60+T_sec)+-12))>=3600,INT((6.21371*((T_min*60+T_sec)+-12))/3600)&":"&TEXT(INT(MOD((6.21371*((T_min*60+T_sec)+-12)),3600)/60),"00")&":"&TEXT(MOD((6.21371*((T_min*60+T_sec)+-12)),60),"00"),INT((6.21371*((T_min*60+T_sec)+-12))/60)&":"&TEXT(MOD((6.21371*((T_min*60+T_sec)+-12)),60),"00")) -> 48:28
B28: Half Marathon | C28: 13.10938 | D28: =TEXT(INT((((T_min*60+T_sec)+7))/60),"0")&":"&TEXT(MOD(((T_min*60+T_sec)+7),60),"00")&"/mi" -> 8:07/mi | E28: =IF((13.10938*((T_min*60+T_sec)+7))>=3600,INT((13.10938*((T_min*60+T_sec)+7))/3600)&":"&TEXT(INT(MOD((13.10938*((T_min*60+T_sec)+7)),3600)/60),"00")&":"&TEXT(MOD((13.10938*((T_min*60+T_sec)+7)),60),"00"),INT((13.10938*((T_min*60+T_sec)+7))/60)&":"&TEXT(MOD((13.10938*((T_min*60+T_sec)+7)),60),"00")) -> 1:46:24
B29: Marathon | C29: 26.21876 | D29: =TEXT(INT((((T_min*60+T_sec)+27))/60),"0")&":"&TEXT(MOD(((T_min*60+T_sec)+27),60),"00")&"/mi" -> 8:27/mi | E29: =IF((26.21876*((T_min*60+T_sec)+27))>=3600,INT((26.21876*((T_min*60+T_sec)+27))/3600)&":"&TEXT(INT(MOD((26.21876*((T_min*60+T_sec)+27)),3600)/60),"00")&":"&TEXT(MOD((26.21876*((T_min*60+T_sec)+27)),60),"00"),INT((26.21876*((T_min*60+T_sec)+27))/60)&":"&TEXT(MOD((26.21876*((T_min*60+T_sec)+27)),60),"00")) -> 3:41:33
B31: How to use these
B32: • Update your T pace on the Inputs sheet after each race — the whole table recalibrates.
B33: • Predictions assume typical race-day conditions. Heat, wind, hills, altitude can shift them 10-30 sec/mi.
B34: • Marathon prediction assumes you also do a Marathon Bridge and Marathon Specific block — a marathon straight off Super Base at this pace is not recommended.
B35: • If your race result is significantly under or over the HM prediction here, that's your signal to recalibrate T going forward.

Sheet Coach Philosophy
B2: Coach Philosophy
B3: The twelve principles this plan runs on — synthesized from John Starrett's Stablemaster Speaks.
B5: Principle | C5: What it means
B6: 1. Consistency beats hero workouts. | C6: The runner who executes 90% of an easy plan will beat the runner who nails 2 huge sessions and blows up. Show up. Repeat. Adapt.
B7: 2. Four runs a week is enough. | C7: Line 17874 of the transcripts: 'If they've got four runs, I would give them one run of 65 minutes, one run of 90 minutes easy' — plus two workouts. John coaches sub-3 marathoners on 4 runs a week.
B8: 3. Training is putting money in the bank; racing is spending it. | C8: Race for purpose. Every race has a why. Two or three marathons a year is over-spending. Let the 5K/10K/HM PBs on the journey be the big chunks.
B9: 4. Stimulate, don't annihilate. | C9: Lee Haney's line, adopted by Stazza. Finish every session feeling you could do 1-2 more reps. Forced fitness breaks you — allowed fitness comes and comes.
B10: 5. Easy runs stay easy. | C10: If your easy runs are moderate, your endurance spine can't be tempo. The grey zone eats plans. Elite runners run easy runs slower than most amateurs think possible.
B11: 6. Recovery is training. | C11: Adaptation happens between sessions, not during. Three rest days a week is not laziness — it's engineering. The catapult analogy: pull back to launch further.
B12: 7. Never sacrifice tomorrow's workout for today's. | C12: If Wednesday's session was hard, Thursday's easy run is easy — not 'catch-up' pace. If you dig a hole today, you can't fill it by digging faster tomorrow.
B13: 8. The Super Base is the foundation, not the paint. | C13: It's the hole in the ground. Everything else — Bridge, Marathon Specific — builds on it. Skip it and you get injured or plateau.
B14: 9. Effort > pace. Run by feel. | C14: Elite runners run by feel. T is what you could hold in a 1-hour race today, on this course, in these conditions, feeling this way. Not a threshold from a spreadsheet.
B15: 10. The endurance spine is the cement. | C15: The Saturday long run is what makes the midweek gains stick. Don't race it. Ever. If you race it, you race the whole plan and it breaks.
B16: 11. V-shaped valley of death. | C16: 8x5 → 10x4 → 10x3 → 15x2 → 20x1. Down the V, 5 sec/mi faster each week. Up the V, HOLD the faster pace. The endurance spine is what lets you keep the pace on the way back up.
B17: 12. Race for a marker, not a target. | C17: Races tell you where you are. Come off the Super Base feeling proven, not gassed. The race is a report card, not a final exam.

Sheet Progress Log
B2: Progress Log
B3: One row per day. Dates recalculate from your Start Date. Mark status as you complete workouts — the Dashboard pie chart updates automatically.
B5: Date | C5: Day | D5: Wk | E5: Phase | F5: Planned workout | G5: Status | H5: Actual pace | I5: Actual duration (min) | J5: Notes
B6: =StartDate+0 -> 46237 | C6: Mon | D6: 1 | E6: Tempo Build 1 | F6: Rest / cross-train
B7: =StartDate+1 -> 46238 | C7: Tue | D7: 1 | E7: Tempo Build 1 | F7: Easy 60 min @ T+60
B8: =StartDate+2 -> 46239 | C8: Wed | D8: 1 | E8: Tempo Build 1 | F8: 20 min WU / 20 min @ T / 20 min CD
B9: =StartDate+3 -> 46240 | C9: Thu | D9: 1 | E9: Tempo Build 1 | F9: Rest / cross-train
B10: =StartDate+4 -> 46241 | C10: Fri | D10: 1 | E10: Tempo Build 1 | F10: Easy 60 min @ T+60
B11: =StartDate+5 -> 46242 | C11: Sat | D11: 1 | E11: Tempo Build 1 | F11: 30 min easy / 40 min @ T+20 / 30 min easy
B12: =StartDate+6 -> 46243 | C12: Sun | D12: 1 | E12: Tempo Build 1 | F12: Rest
B13: =StartDate+7 -> 46244 | C13: Mon | D13: 2 | E13: Tempo Build 2 | F13: Rest / cross-train
B14: =StartDate+8 -> 46245 | C14: Tue | D14: 2 | E14: Tempo Build 2 | F14: Easy 60 min @ T+60
B15: =StartDate+9 -> 46246 | C15: Wed | D15: 2 | E15: Tempo Build 2 | F15: 20 min easy / 20 min @ T / 5 min easy / 10 min @ T / 20 min easy
B16: =StartDate+10 -> 46247 | C16: Thu | D16: 2 | E16: Tempo Build 2 | F16: Rest / cross-train
B17: =StartDate+11 -> 46248 | C17: Fri | D17: 2 | E17: Tempo Build 2 | F17: Easy 60 min @ T+60
B18: =StartDate+12 -> 46249 | C18: Sat | D18: 2 | E18: Tempo Build 2 | F18: 30 min easy / 50 min @ T+20 / 30 min easy
B19: =StartDate+13 -> 46250 | C19: Sun | D19: 2 | E19: Tempo Build 2 | F19: Rest
B20: =StartDate+14 -> 46251 | C20: Mon | D20: 3 | E20: Tempo Build 3 | F20: Rest / cross-train
B21: =StartDate+15 -> 46252 | C21: Tue | D21: 3 | E21: Tempo Build 3 | F21: Easy 60 min @ T+60
B22: =StartDate+16 -> 46253 | C22: Wed | D22: 3 | E22: Tempo Build 3 | F22: 20 min easy / 20 min @ T / 5 min easy / 15 min @ T / 20 min easy
B23: =StartDate+17 -> 46254 | C23: Thu | D23: 3 | E23: Tempo Build 3 | F23: Rest / cross-train
B24: =StartDate+18 -> 46255 | C24: Fri | D24: 3 | E24: Tempo Build 3 | F24: Easy 60 min @ T+60
B25: =StartDate+19 -> 46256 | C25: Sat | D25: 3 | E25: Tempo Build 3 | F25: 30 min easy / 60 min @ T+20 / 30 min easy
B26: =StartDate+20 -> 46257 | C26: Sun | D26: 3 | E26: Tempo Build 3 | F26: Rest
B27: =StartDate+21 -> 46258 | C27: Mon | D27: 4 | E27: Tempo Build 4 | F27: Rest / cross-train
B28: =StartDate+22 -> 46259 | C28: Tue | D28: 4 | E28: Tempo Build 4 | F28: Easy 60 min @ T+60
B29: =StartDate+23 -> 46260 | C29: Wed | D29: 4 | E29: Tempo Build 4 | F29: 20 min easy / 2x 20 min @ T off 5 min easy / 20 min easy
B30: =StartDate+24 -> 46261 | C30: Thu | D30: 4 | E30: Tempo Build 4 | F30: Rest / cross-train
B31: =StartDate+25 -> 46262 | C31: Fri | D31: 4 | E31: Tempo Build 4 | F31: Easy 60 min @ T+60
B32: =StartDate+26 -> 46263 | C32: Sat | D32: 4 | E32: Tempo Build 4 | F32: 30 min easy / 40 min @ T+15 / 30 min easy
B33: =StartDate+27 -> 46264 | C33: Sun | D33: 4 | E33: Tempo Build 4 | F33: Rest
B34: =StartDate+28 -> 46265 | C34: Mon | D34: 5 | E34: Transition into V | F34: Rest / cross-train
B35: =StartDate+29 -> 46266 | C35: Tue | D35: 5 | E35: Transition into V | F35: Easy 60 min @ T+60
B36: =StartDate+30 -> 46267 | C36: Wed | D36: 5 | E36: Transition into V | F36: 20 min WU / 20 min @ T / 5 easy / 10 min @ T-5 / 5 easy / 2x 5 min @ T-10 off 3 min / 20 min CD
B37: =StartDate+31 -> 46268 | C37: Thu | D37: 5 | E37: Transition into V | F37: Rest / cross-train
B38: =StartDate+32 -> 46269 | C38: Fri | D38: 5 | E38: Transition into V | F38: Easy 60 min @ T+60
B39: =StartDate+33 -> 46270 | C39: Sat | D39: 5 | E39: Transition into V | F39: 30 min easy / 50 min @ T+15 / 30 min easy
B40: =StartDate+34 -> 46271 | C40: Sun | D40: 5 | E40: Transition into V | F40: Rest
B41: =StartDate+35 -> 46272 | C41: Mon | D41: 6 | E41: Descent 1: Precipice | F41: Rest / cross-train
B42: =StartDate+36 -> 46273 | C42: Tue | D42: 6 | E42: Descent 1: Precipice | F42: Easy 60 min @ T+60
...
